Workbook

Sheet Regras Premiação
C2: Promotor | D2: A+ > 300.000 | E2: BASE: | F2: 1500 | G2: A+ | K2: Coordenador | L2: A+ | Venda > 1.750.000 | M2: BASE: | N2: 2000 | T2: PROMOTORIA | U2: RESUMO DE NÍVEIS | Z2: COORDENAÇÃO | AA2: RESUMO DE NÍVEIS | AG2: Supervisor | AH2: - | AI2: Set | AO2: Gerente | AP2: - | AQ2: Set
A3: Regras: | C3: Objetivo | I3: Regras: | K3: Objetivo | T3: NÍVEL | U3: 0.9 | V3: 1 | W3: 1.15 | Z3: NÍVEL | AA3: 0.9 | AB3: 1 | AC3: 1.15 | AE3: Regras: | AG3: Objetivo | AM3: Regras: | AO3: Objetivo
A4: 1º | C4: Chegar na Meta Sell-Out | E4: 0.9 | F4: 1 | G4: 1.15 | I4: 1º | K4: Chegar na Meta Sell-Out | M4: 0.9 | N4: 1 | O4: 1.15 | T4: A+ | U4: =E19 -> 100 | V4: =F19 -> 200 | W4: =G19 -> 270 | Z4: A+ | AA4: 135 | AB4: 270 | AC4: 350 | AE4: 1º | AG4: Chegar na Meta Sell-Out | AI4: 0.9 | AJ4: 1 | AK4: 1.15 | AM4: 1º | AO4: Chegar na Meta Sell-Out | AQ4: 0.9 | AR4: 1 | AS4: 1.15
C5: A: | D5: Atingimento Total Master | E5: =E18/$F$29 -> 0.0625 | F5: =F18/$F$29 -> 0.125 | G5: =G18/$F$29 -> 0.1875 | K5: A: | L5: Atingimento Total Master | M5: 0.05 | N5: 0.1 | O5: 0.15 | T5: A | U5: =E47 -> 85 | V5: =F47 -> 170 | W5: =G47 -> 200 | Z5: A | AA5: 112.5 | AB5: 225 | AC5: 270 | AG5: A: | AH5: Atingimento Total Master | AI5: 130 | AJ5: 250 | AK5: 360 | AO5: A: | AP5: Atingimento Total Master | AQ5: =MROUND(AI5/$AK5*$AS5,10) -> 180 | AR5: =MROUND(AJ5/$AK5*$AS5,10) -> 350 | AS5: 500
C6: B: | D6: Atingimento Individual Avine | E6: =E19/$F$29 -> 0.083333333 | F6: =F19/$F$29 -> 0.16666667 | G6: =G19/$F$29 -> 0.225 | K6: B: | L6: Atingimento Individual Avine | M6: 0.075 | N6: 0.15 | O6: 0.2 | T6: B | U6: =E76 -> 70 | V6: =F76 -> 140 | W6: =G76 -> 175 | Z6: B | AA6: 85 | AB6: 170 | AC6: 220 | AG6: B: | AH6: Atingimento Individual Avine | AI6: 175 | AJ6: 350 | AK6: 440 | AO6: B: | AP6: Atingimento Individual Avine | AQ6: =MROUND(AI6/$AK6*$AS6,10) -> 200 | AR6: =MROUND(AJ6/$AK6*$AS6,10) -> 400 | AS6: 500
C7: C: | D7: Atingimento Individual Capp | E7: =E20/$F$29 -> 0.083333333 | F7: =F20/$F$29 -> 0.16666667 | G7: =G20/$F$29 -> 0.225 | K7: C: | L7: Atingimento Individual Capp | M7: 0.15 | N7: 0.3 | O7: 0.4 | T7: C | U7: =E105 -> 50 | V7: =F105 -> 100 | W7: =G105 -> 125 | AG7: C: | AH7: Atingimento Individual Capp | AI7: 175 | AJ7: 350 | AK7: 440 | AO7: =AG7 -> C: | AP7: Atingimento Individual Capp | AQ7: =MROUND(AI7/$AK7*$AS7,10) -> 200 | AR7: =MROUND(AJ7/$AK7*$AS7,10) -> 400 | AS7: 500
C8: D: | D8: Atingimento Individual Famosa | E8: =E21/$F$29 -> 0.083333333 | F8: =F21/$F$29 -> 0.16666667 | G8: =G21/$F$29 -> 0.225 | AG8: D: | AH8: Atingimento Individual Famosa | AI8: 175 | AJ8: 350 | AK8: 440 | AO8: D: | AP8: Atingimento Individual Famosa | AQ8: =MROUND(AI8/$AK8*$AS8,10) -> 200 | AR8: =MROUND(AJ8/$AK8*$AS8,10) -> 400 | AS8: 500
C9: E: | D9: Atingimento Individual S&V | E9: =E22/$F$29 -> 0 | F9: =F22/$F$29 -> 0 | G9: =G22/$F$29 -> 0 | K9: D: | L9: Atingimento Individual Famosa | M9: 0.075 | N9: 0.15 | O9: 0.2 | AE9: 2 | AG9: Devolução < 1,5% | AH9: Atingimento Individual Avine | AI9: 400 | AJ9: 400 | AK9: 400 | AM9: 2 | AO9: Devolução < 1,5% | AP9: Atingimento Individual Avine | AQ9: 500 | AR9: 500 | AS9: 500
C10: F: | D10: Atingimento Individual Trebeschi | E10: =E23/$F$29 -> 0 | F10: =F23/$F$29 -> 0 | G10: =G23/$F$29 -> 0
AE11: 3 | AG11: Avaliação Gestor | AH11: Atingimento Total Master | AI11: 400 | AJ11: 400 | AK11: 400 | AM11: 3 | AO11: Avaliação Gestor | AP11: Atingimento Total Master | AQ11: 565 | AR11: 565 | AS11: 565
A12: 2 | C12: Devolução <= 1% | D12: Atingimento Individual Avine | E12: =E25/$F$29 -> 0.1875 | F12: =F25/$F$29 -> 0.1875 | G12: =G25/$F$29 -> 0.1875 | I12: 2 | K12: Devolução < 1% | L12: Atingimento Individual Avine | M12: 0.15 | N12: 0.15 | O12: 0.15 | T12: Premiação Master
T13: Resultado Master | U13: 0.9 | V13: 1 | W13: 1.15 | AH13: Total | AI13: =SUM(AI5:AI11) -> 1455 | AJ13: =SUM(AJ5:AJ11) -> 2100 | AK13: =SUM(AK5:AK11) -> 2480 | AP13: Total | AQ13: =SUM(AQ5:AQ11) -> 1845 | AR13: =SUM(AR5:AR11) -> 2615 | AS13: =SUM(AS5:AS11) -> 3065
A14: 3 | C14: Avaliação Gestor | D14: Atingimento Total Master | E14: =E27/$F$29 -> 0.1875 | F14: =F27/$F$29 -> 0.1875 | G14: 0.15 | I14: 3 | K14: Avaliação Gestor | L14: Atingimento Total Master | M14: 0.15 | N14: 0.15 | O14: 0.15 | T14: Promotor | U14: 75 | V14: 150 | W14: 225
E15: =SUM(E5:E14) -> 0.6875 | F15: =SUM(F5:F14) -> 1 | G15: =SUM(G5:G14) -> 1.2 | M15: 0.65 | N15: 1 | O15: 1.2 | T15: Coordenador | U15: 100 | V15: 200 | W15: 300 | AH15: Total Edinaldo | AI15: 1350 | AP15: Total Raianne | AQ15: 1420
A16: Regras: | C16: Objetivo | I16: Regras: | K16: Objetivo
A17: 1º | C17: Chegar na Meta Sell-Out | E17: 0.9 | F17: 1 | G17: 1.15 | I17: 1º | K17: Chegar na Meta Sell-Out | M17: 0.9 | N17: 1 | O17: 1.15
C18: A: | D18: Atingimento Total Master | E18: 75 | F18: 150 | G18: 225 | K18: A: | L18: Atingimento Total Master | M18: 100 | N18: 200 | O18: 300
C19: B: | D19: Atingimento Individual Avine | E19: 100 | F19: 200 | G19: 270 | K19: B: | L19: Atingimento Individual Avine | M19: =N19/2 -> 135 | N19: 270 | O19: 350 | T19: PROMOTORIA | U19: Média
C20: C: | D20: Atingimento Individual Capp | E20: 100 | F20: 200 | G20: 270 | K20: C: | L20: Atingimento Individual Capp | M20: =N20/2 -> 135 | N20: 270 | O20: 350 | T20: NÍVEL | U20: 0.6
C21: D: | D21: Atingimento Individual Famosa / Florestal | E21: 100 | F21: 200 | G21: 270 | K21: D: | L21: Atingimento Individual Famosa | M21: =N21/2 -> 135 | N21: 270 | O21: 350 | T21: A+ | U21: =U20*F29 -> 720
C22: E: | D22: Atingimento Individual S&V | K22: E: | L22: Atingimento Individual S&V | M22: =N22/2 -> 135 | N22: 270 | O22: 350 | T22: A | U22: =U20*F57 -> 972
C23: F: | D23: Atingimento Individual Trebeschi
T24: B | U24: =U20*F86 -> 864
A25: 2 | C25: Devolução <= 1.5% | D25: Atingimento Individual Avine | E25: 225 | F25: 225 | G25: 225 | I25: 2 | K25: Devolução < 1,5% | L25: Atingimento Individual Avine | M25: 300 | N25: 300 | O25: 300 | T25: C | U25: =U20*F115 -> 540
A27: 3 | C27: Avaliação APP | D27: Avaliação | E27: 225 | F27: 225 | G27: 225 | I27: 3 | K27: Avaliação Gestor | L27: Atingimento Total Master | M27: 300 | N27: 300 | O27: 300
D29: Total | E29: =SUM(E18:E27) -> 825 | F29: =SUM(F18:F27) -> 1200 | G29: =SUM(G18:G27) -> 1485 | L29: Total ( Incluindo a marca do Mês) | M29: =SUM(M18:M27)+M22 -> 1375 | N29: =SUM(N18:N27)+N22 -> 2150 | O29: =SUM(O18:O27)+O22 -> 2650 | T29: PROMOTORIA | U29: Premiação por Marca | Z29: - | AA29: RESUMO DE NÍVEIS
T30: NÍVEL ( Sell out ) | U30: 0.9 | V30: 1 | W30: 1.15 | Z30: NÍVEL | AA30: 0.9 | AB30: 1 | AC30: 1.15 | AD30: Dev
C31: Promotor | D31: A | Venda > 260.000 | E31: BASE: | F31: 1500 | G31: A | K31: Coordenador | L31: A | Venda > 1.000.000 | M31: BASE: | N31: 2000 | T31: A+ ( 300.000+ ) | U31: =E19 -> 100 | V31: =F19 -> 200 | W31: =G19 -> 270 | Z31: Supervisão | AA31: 150 | AB31: 350 | AC31: 440 | AD31: 400
A32: Regras: | C32: Objetivo | I32: Regras: | K32: Objetivo | T32: A ( 260.000+ ) | U32: =E47 -> 85 | V32: =F47 -> 170 | W32: =G47 -> 200 | Z32: Assistente | AA32: 100 | AB32: 200 | AC32: 250 | AD32: 250
A33: 1º | C33: Chegar na Meta Sell-Out | E33: 0.9 | F33: 1 | G33: 1.15 | I33: 1º | K33: Chegar na Meta Sell-Out | M33: 0.9 | N33: 1 | O33: 1.15 | T33: B ( 200.000+ ) | U33: =E76 -> 70 | V33: =F76 -> 140 | W33: =G76 -> 175 | Z33: Auxiliar | AA33: 75 | AB33: 150 | AC33: 225 | AD33: 225
C34: A: | D34: Atingimento Total Master | E34: 0.05 | F34: 0.1 | G34: 0.15 | K34: A: | L34: Atingimento Total Master | M34: 0.05 | N34: 0.1 | O34: 0.15 | T34: C ( Até 200.000 ) | U34: =E105 -> 50 | V34: =F105 -> 100 | W34: =G105 -> 125 | Z34: Gerente | AA34: 170 | AB34: 400 | AC34: 500 | AD34: 500
C35: B: | D35: Atingimento Individual Avine | E35: 0.0625 | F35: 0.125 | G35: 0.15 | K35: B: | L35: Atingimento Individual Avine | M35: 0.0625 | N35: 0.125 | O35: 0.15
C36: C: | D36: Atingimento Individual Capp | E36: 0.125 | F36: 0.25 | G36: 0.3 | K36: C: | L36: Atingimento Individual Capp | M36: 0.125 | N36: 0.25 | O36: 0.3
C37: D: | D37: Atingimento Individual Famosa | E37: 0.0625 | F37: 0.125 | G37: 0.15 | K37: D: | L37: Atingimento Individual Famosa | M37: 0.0625 | N37: 0.125 | O37: 0.15 | T37: Aplicativo
T38: Função | V38: 0.9 | W38: 1
T39: Estoque | V39: 56.25 | W39: =W40 -> 112.5
A40: 2 | C40: Devolução <= 1% | D40: Atingimento Individual Avine | E40: 0.15 | F40: 0.15 | G40: 0.15 | I40: 2 | K40: Devolução < 1% | L40: Atingimento Individual Avine | M40: 0.15 | N40: 0.15 | O40: 0.15 | T40: Pesquisa de Preço | V40: =V39 -> 56.25 | W40: =V40*2 -> 112.5
A42: 3 | C42: Avaliação Gestor | D42: Atingimento Total Master | E42: 0.15 | F42: 0.15 | G42: 0.15 | I42: 3 | K42: Avaliação Gestor | L42: Atingimento Total Master | M42: 0.15 | N42: 0.15 | O42: 0.15
E43: 0.6 | F43: 0.9 | G43: 1.05 | M43: 0.6 | N43: 0.9 | O43: 1.05 | T43: Devolução Avine
A44: Regras: | C44: Objetivo | I44: Regras: | K44: Objetivo | T44: Atingimento <= 1.5% | V44: 225
...

Sheet Base App
A2: Promotor | B2: Dias_Enviados | C2: Meta | D2: Dias_Abonados | E2: Dias_Efetivos | F2: % | G2: % Estoque | H2: Status Meta | I2: Status Promotor | J2: Pesq. Preço R$ | K2: Estoque | L2: Total
A3: ANDRESSA NEVES | B3: 17 | C3: 17 | D3: 1 | E3: 18 | F3: =IFERROR(Base_APP[[#This Row],[Dias_Enviados]]/(Base_APP[[#This Row],[Meta]]-Base_APP[[#This Row],[Dias_Abonados]]),1) -> 1.0625 | I3: =IFERROR(VLOOKUP(Base_APP[[#This Row],[Promotor]],Promotores[Promotor],1,0),"") -> ANDRESSA NEVES
A4: ANGELA | B4: 14 | C4: 17 | D4: 1 | E4: 15 | F4: =IFERROR(Base_APP[[#This Row],[Dias_Enviados]]/(Base_APP[[#This Row],[Meta]]-Base_APP[[#This Row],[Dias_Abonados]]),1) -> 0.875 | I4: =IFERROR(VLOOKUP(Base_APP[[#This Row],[Promotor]],Promotores[Promotor],1,0),"") -> ANGELA
A5: CARLOS HENRIQUE | B5: 19 | C5: 17 | D5: 1 | E5: 20 | F5: =IFERROR(Base_APP[[#This Row],[Dias_Enviados]]/(Base_APP[[#This Row],[Meta]]-Base_APP[[#This Row],[Dias_Abonados]]),1) -> 1.1875 | I5: =IFERROR(VLOOKUP(Base_APP[[#This Row],[Promotor]],Promotores[Promotor],1,0),"") -> CARLOS HENRIQUE
A6: CLEANE BRANDAO | B6: 18 | C6: 17 | D6: 1 | E6: 19 | F6: =IFERROR(Base_APP[[#This Row],[Dias_Enviados]]/(Base_APP[[#This Row],[Meta]]-Base_APP[[#This Row],[Dias_Abonados]]),1) -> 1.125 | I6: =IFERROR(VLOOKUP(Base_APP[[#This Row],[Promotor]],Promotores[Promotor],1,0),"") -> CLEANE BRANDAO
A7: DANIELE | B7: 12 | C7: 17 | D7: 4 | E7: 16 | F7: =IFERROR(Base_APP[[#This Row],[Dias_Enviados]]/(Base_APP[[#This Row],[Meta]]-Base_APP[[#This Row],[Dias_Abonados]]),1) -> 0.92307692 | I7: =IFERROR(VLOOKUP(Base_APP[[#This Row],[Promotor]],Promotores[Promotor],1,0),"") -> DANIELE
A8: DIEGO | B8: 25 | C8: 17 | D8: 1 | E8: 26 | F8: =IFERROR(Base_APP[[#This Row],[Dias_Enviados]]/(Base_APP[[#This Row],[Meta]]-Base_APP[[#This Row],[Dias_Abonados]]),1) -> 1.5625 | I8: =IFERROR(VLOOKUP(Base_APP[[#This Row],[Promotor]],Promotores[Promotor],1,0),"") -> DIEGO
A9: EDINALDO | B9: 4 | C9: 17 | D9: 0 | E9: 4 | F9: =IFERROR(Base_APP[[#This Row],[Dias_Enviados]]/(Base_APP[[#This Row],[Meta]]-Base_APP[[#This Row],[Dias_Abonados]]),1) -> 0.23529412 | I9: =IFERROR(VLOOKUP(Base_APP[[#This Row],[Promotor]],Promotores[Promotor],1,0),"")
A10: ELENILDE | B10: 14 | C10: 17 | D10: 1 | E10: 15 | F10: =IFERROR(Base_APP[[#This Row],[Dias_Enviados]]/(Base_APP[[#This Row],[Meta]]-Base_APP[[#This Row],[Dias_Abonados]]),1) -> 0.875 | I10: =IFERROR(VLOOKUP(Base_APP[[#This Row],[Promotor]],Promotores[Promotor],1,0),"") -> ELENILDE
A11: FABIANE | B11: 21 | C11: 17 | D11: 0 | E11: 21 | F11: =IFERROR(Base_APP[[#This Row],[Dias_Enviados]]/(Base_APP[[#This Row],[Meta]]-Base_APP[[#This Row],[Dias_Abonados]]),1) -> 1.2352941 | I11: =IFERROR(VLOOKUP(Base_APP[[#This Row],[Promotor]],Promotores[Promotor],1,0),"") -> FABIANE
A12: FERNANDO | B12: 16 | C12: 17 | D12: 1 | E12: 17 | F12: =IFERROR(Base_APP[[#This Row],[Dias_Enviados]]/(Base_APP[[#This Row],[Meta]]-Base_APP[[#This Row],[Dias_Abonados]]),1) -> 1 | I12: =IFERROR(VLOOKUP(Base_APP[[#This Row],[Promotor]],Promotores[Promotor],1,0),"") -> FERNANDO
A13: GILERLESON | B13: 24 | C13: 17 | D13: 1 | E13: 25 | F13: =IFERROR(Base_APP[[#This Row],[Dias_Enviados]]/(Base_APP[[#This Row],[Meta]]-Base_APP[[#This Row],[Dias_Abonados]]),1) -> 1.5 | I13: =IFERROR(VLOOKUP(Base_APP[[#This Row],[Promotor]],Promotores[Promotor],1,0),"") -> GILERLESON
A14: GUILHERME | B14: 6 | C14: 17 | D14: 1 | E14: 7 | F14: =IFERROR(Base_APP[[#This Row],[Dias_Enviados]]/(Base_APP[[#This Row],[Meta]]-Base_APP[[#This Row],[Dias_Abonados]]),1) -> 0.375 | I14: =IFERROR(VLOOKUP(Base_APP[[#This Row],[Promotor]],Promotores[Promotor],1,0),"") -> GUILHERME
... A35: WILKENIA | B35: 14 | C35: 17 | D35: 1 | E35: 15 | F35: =IFERROR(Base_APP[[#This Row],[Dias_Enviados]]/(Base_APP[[#This Row],[Meta]]-Base_APP[[#This Row],[Dias_Abonados]]),1) -> 0.875 | I35: =IFERROR(VLOOKUP(Base_APP[[#This Row],[Promotor]],Promotores[Promotor],1,0),"") -> WILKENIA

Sheet Dados
A1: Cod Avi | B1: COD | C1: LOJA | D1: Nome Loja | E1: PROMOTOR | F1: REGIONAL | G1: Mês | H1: Coordenador | J1: COD Loja | K1: LOJA | L1: Nome Loja | M1: Prom Avine | N1: Prom Frutas | O1: Mês | P1: Coordenador | Q1: Supervisor | R1: CD | S1: Gerente | T1: Rede | U1: Grupo | V1: Resultado | W1: Meta | X1: Result Capp | Y1: Meta Capp
A2: 18047 | B2: 116 | C2: CD 116 | D2: CD 116 | E2: William | F2: CD | G2: DEZ | H2: CLEISSE | J2: 1 | K2: Mat Hiper Balsas | L2: Hiper Balsas | M2: ROSICLEIA | N2: ROSICLEIA | O2: JUL | P2: THIEUDE | Q2: Edinaldo | R2: CD 87 | S2: Sim | T2: Mateus | U2: Varejo | V2: =IFERROR(VLOOKUP(Rotas_Geral[[#This Row],[Nome Loja]],#REF!,3,0),0) -> 0 | W2: =IFERROR(VLOOKUP(Rotas_Geral[[#This Row],[Nome Loja]],#REF!,4,0),0) -> 0 | X2: =IFERROR(VLOOKUP(Rotas_Geral[[#This Row],[Nome Loja]],#REF!,3,0),0) -> 0 | Y2: =IFERROR(VLOOKUP(Rotas_Geral[[#This Row],[Nome Loja]],#REF!,4,0),0) -> 0
A3: 11081 | B3: 87 | C3: CD 87 | D3: CD 87 | E3: Nargila | F3: CD | G3: DEZ | H3: FLAVIO | J3: 2 | K3: MAT. I. CE | L3: Ceará | M3: RARIEL | N3: ANGELA | O3: JUL | P3: THIEUDE | Q3: Edinaldo | R3: CD 87 | S3: Sim | T3: Mateus | U3: Varejo | V3: =IFERROR(VLOOKUP(Rotas_Geral[[#This Row],[Nome Loja]],#REF!,3,0),0) -> 0 | W3: =IFERROR(VLOOKUP(Rotas_Geral[[#This Row],[Nome Loja]],#REF!,4,0),0) -> 0 | X3: =IFERROR(VLOOKUP(Rotas_Geral[[#This Row],[Nome Loja]],#REF!,3,0),0) -> 0 | Y3: =IFERROR(VLOOKUP(Rotas_Geral[[#This Row],[Nome Loja]],#REF!,4,0),0) -> 0
A4: 18002 | B4: 266 | C4: MAT SOBRAL | D4: Mix Sobral | E4: LUCAS | F4: Ceará | G4: DEZ | H4: EDINALDO | J4: 3 | K4: MAT. S. INES | L4: Sup Santa Inês | M4: BEATRIZ | N4: BEATRIZ | O4: JUL | P4: LILIANE | Q4: Edinaldo | R4: CD 116 | S4: Sim | T4: Mateus | U4: Varejo | V4: =IFERROR(VLOOKUP(Rotas_Geral[[#This Row],[Nome Loja]],#REF!,3,0),0) -> 0 | W4: =IFERROR(VLOOKUP(Rotas_Geral[[#This Row],[Nome Loja]],#REF!,4,0),0) -> 0 | X4: =IFERROR(VLOOKUP(Rotas_Geral[[#This Row],[Nome Loja]],#REF!,3,0),0) -> 0 | Y4: =IFERROR(VLOOKUP(Rotas_Geral[[#This Row],[Nome Loja]],#REF!,4,0),0) -> 0
A5: 19826 | B5: 264 | C5: Mateus Tianguá | D5: Tianguá | E5: VAGO | F5: Ceará | G5: DEZ | H5: ALESSANDRO | J5: 4 | K5: MAT. I. GOIA | L5: Goiás | M5: NARGILA | N5: ANGELA | O5: JUL | P5: THIEUDE | Q5: Edinaldo | R5: CD 87 | S5: Sim | T5: Mateus | U5: Mix | V5: =IFERROR(VLOOKUP(Rotas_Geral[[#This Row],[Nome Loja]],#REF!,3,0),0) -> 0 | W5: =IFERROR(VLOOKUP(Rotas_Geral[[#This Row],[Nome Loja]],#REF!,4,0),0) -> 0 | X5: =IFERROR(VLOOKUP(Rotas_Geral[[#This Row],[Nome Loja]],#REF!,3,0),0) -> 0 | Y5: =IFERROR(VLOOKUP(Rotas_Geral[[#This Row],[Nome Loja]],#REF!,4,0),0) -> 0
A6: 19825 | B6: 461 | C6: Camino Urb. Santos | D6: Camino Urb. Santos | E6: VAGO | F6: MA Norte | G6: DEZ | H6: ALESSANDRO | J6: 5 | K6: MAT. COHAB | L6: Cohab | M6: SILDIENY | N6: CLEISSE | O6: JUL | P6: CARLA | Q6: Edinaldo | R6: CD 116 | S6: Sim | T6: Mateus | U6: Varejo | V6: =IFERROR(VLOOKUP(Rotas_Geral[[#This Row],[Nome Loja]],#REF!,3,0),0) -> 0 | W6: =IFERROR(VLOOKUP(Rotas_Geral[[#This Row],[Nome Loja]],#REF!,4,0),0) -> 0 | X6: =IFERROR(VLOOKUP(Rotas_Geral[[#This Row],[Nome Loja]],#REF!,3,0),0) -> 0 | Y6: =IFERROR(VLOOKUP(Rotas_Geral[[#This Row],[Nome Loja]],#REF!,4,0),0) -> 0
A7: 1283 | B7: 459 | C7: Camino Cururupu | D7: Camino Cururupu | E7: VAGO | F7: MA Norte | G7: DEZ | H7: THIEUDE | J7: 7 | K7: MAT. COHAMA | L7: Cohama | M7: ELENILDE | N7: MAILANE | O7: JUL | P7: CARLA | Q7: Edinaldo | R7: CD 116 | S7: Sim | T7: Mateus | U7: Varejo | V7: =IFERROR(VLOOKUP(Rotas_Geral[[#This Row],[Nome Loja]],#REF!,3,0),0) -> 0 | W7: =IFERROR(VLOOKUP(Rotas_Geral[[#This Row],[Nome Loja]],#REF!,4,0),0) -> 0 | X7: =IFERROR(VLOOKUP(Rotas_Geral[[#This Row],[Nome Loja]],#REF!,3,0),0) -> 0 | Y7: =IFERROR(VLOOKUP(Rotas_Geral[[#This Row],[Nome Loja]],#REF!,4,0),0) -> 0
A8: 14254 | B8: 427 | C8: CAMINO ARARI | D8: Camino Arari | E8: VAGO | F8: MA Norte | G8: DEZ | H8: EDINALDO | J8: 8 | K8: MAT. TURU | L8: Turuzinho | M8: SILDIENY | N8: Kelsiane | O8: JUL | P8: CARLA | Q8: Edinaldo | R8: CD 116 | S8: Sim | T8: Mateus | U8: Varejo | V8: =IFERROR(VLOOKUP(Rotas_Geral[[#This Row],[Nome Loja]],#REF!,3,0),0) -> 0 | W8: =IFERROR(VLOOKUP(Rotas_Geral[[#This Row],[Nome Loja]],#REF!,4,0),0) -> 0 | X8: =IFERROR(VLOOKUP(Rotas_Geral[[#This Row],[Nome Loja]],#REF!,3,0),0) -> 0 | Y8: =IFERROR(VLOOKUP(Rotas_Geral[[#This Row],[Nome Loja]],#REF!,4,0),0) -> 0
A9: 19408 | B9: 434 | C9: Camino Barreirinhas | D9: Camino Barreirinhas | E9: ANDRESSA NEVES | F9: MA Norte | G9: DEZ | H9: THIEUDE | J9: 11 | K9: MAT. CIDAD O | L9: Cidade Operária | M9: ALEXANDRE | N9: Pat. Cristina | O9: JUL | P9: CARLA | Q9: Edinaldo | R9: CD 116 | S9: Sim | T9: Mateus | U9: Varejo | V9: =IFERROR(VLOOKUP(Rotas_Geral[[#This Row],[Nome Loja]],#REF!,3,0),0) -> 0 | W9: =IFERROR(VLOOKUP(Rotas_Geral[[#This Row],[Nome Loja]],#REF!,4,0),0) -> 0 | X9: =IFERROR(VLOOKUP(Rotas_Geral[[#This Row],[Nome Loja]],#REF!,3,0),0) -> 0 | Y9: =IFERROR(VLOOKUP(Rotas_Geral[[#This Row],[Nome Loja]],#REF!,4,0),0) -> 0
A10: 19194 | B10: 435 | C10: CAMINO COROATA | D10: Camino Coroatá | E10: VAGO | F10: MA Norte | G10: DEZ | H10: THIEUDE | J10: 12 | K10: MAT.RIO ANIL | L10: Rio Anil | M10: ALEXANDRE | N10: CLEISSE | O10: JUL | P10: CARLA | Q10: Edinaldo | R10: CD 116 | S10: Sim | T10: Mateus | U10: Varejo | V10: =IFERROR(VLOOKUP(Rotas_Geral[[#This Row],[Nome Loja]],#REF!,3,0),0) -> 0 | W10: =IFERROR(VLOOKUP(Rotas_Geral[[#This Row],[Nome Loja]],#REF!,4,0),0) -> 0 | X10: =IFERROR(VLOOKUP(Rotas_Geral[[#This Row],[Nome Loja]],#REF!,3,0),0) -> 0 | Y10: =IFERROR(VLOOKUP(Rotas_Geral[[#This Row],[Nome Loja]],#REF!,4,0),0) -> 0
A11: 1286 | B11: 445 | C11: CAMINO ITAPECURU | D11: Camino Itapecuru | E11: RAIMUNDO | F11: MA Norte | G11: DEZ | H11: THIEUDE | J11: 15 | K11: MAT. ACAILAN | L11: Sup Açailândia | M11: ISRAEL | N11: ISRAEL | O11: JUL | P11: THIEUDE | Q11: Edinaldo | R11: CD 87 | S11: Sim | T11: Mateus | U11: Varejo | V11: =IFERROR(VLOOKUP(Rotas_Geral[[#This Row],[Nome Loja]],#REF!,3,0),0) -> 0 | W11: =IFERROR(VLOOKUP(Rotas_Geral[[#This Row],[Nome Loja]],#REF!,4,0),0) -> 0 | X11: =IFERROR(VLOOKUP(Rotas_Geral[[#This Row],[Nome Loja]],#REF!,3,0),0) -> 0 | Y11: =IFERROR(VLOOKUP(Rotas_Geral[[#This Row],[Nome Loja]],#REF!,4,0),0) -> 0
A12: 15639 | B12: 439 | C12: CAMINO MIRANDA | D12: Camino Miranda | E12: RAIMUNDO | F12: MA Norte | G12: DEZ | H12: THIEUDE | J12: 16 | K12: MAT. CALHAU2 | L12: Calhau | M12: CLEANE BRANDAO | N12: MAILANE | O12: JUL | P12: CARLA | Q12: Edinaldo | R12: CD 116 | S12: Sim | T12: Mateus | U12: Varejo | V12: =IFERROR(VLOOKUP(Rotas_Geral[[#This Row],[Nome Loja]],#REF!,3,0),0) -> 0 | W12: =IFERROR(VLOOKUP(Rotas_Geral[[#This Row],[Nome Loja]],#REF!,4,0),0) -> 0 | X12: =IFERROR(VLOOKUP(Rotas_Geral[[#This Row],[Nome Loja]],#REF!,3,0),0) -> 0 | Y12: =IFERROR(VLOOKUP(Rotas_Geral[[#This Row],[Nome Loja]],#REF!,4,0),0) -> 0
A13: 9456 | B13: 424 | C13: CAMINO ROSARIO | D13: Camino Rosário | E13: VAGO | F13: MA Norte | G13: DEZ | H13: THIEUDE | J13: 17 | K13: MAT. GUAJAJ | L13: Tirirical | M13: VAGO | N13: Pat. Cristina | O13: JUL | P13: CARLA | Q13: Edinaldo | R13: CD 116 | S13: Não | T13: Mateus | U13: Mix | V13: =IFERROR(VLOOKUP(Rotas_Geral[[#This Row],[Nome Loja]],#REF!,3,0),0) -> 0 | W13: =IFERROR(VLOOKUP(Rotas_Geral[[#This Row],[Nome Loja]],#REF!,4,0),0) -> 0 | X13: =IFERROR(VLOOKUP(Rotas_Geral[[#This Row],[Nome Loja]],#REF!,3,0),0) -> 0 | Y13: =IFERROR(VLOOKUP(Rotas_Geral[[#This Row],[Nome Loja]],#REF!,4,0),0) -> 0
... A24: 15415 | B24: 446 | C24: Camino Santa Luzia | D24: Camino Santa Luzia | E24: VAGO | F24: MA Norte | G24: DEZ | H24: THIEUDE | J24: 30 | K24: MAT BACANGA | L24: Bacanga | M24: NATHALIA | N24: WILIANE | O24: JUL | P24: CARLA | Q24: Edinaldo | R24: CD 116 | S24: Sim | T24: Mateus | U24: Varejo | V24: =IFERROR(VLOOKUP(Rotas_Geral[[#This Row],[Nome Loja]],#REF!,3,0),0) -> 0 | W24: =IFERROR(VLOOKUP(Rotas_Geral[[#This Row],[Nome Loja]],#REF!,4,0),0) -> 0 | X24: =IFERROR(VLOOKUP(Rotas_Geral[[#This Row],[Nome Loja]],#REF!,3,0),0) -> 0 | Y24: =IFERROR(VLOOKUP(Rotas_Geral[[#This Row],[Nome Loja]],#REF!,4,0),0) -> 0
A25: #N/A | B25: 452 | C25: Camino Vitorino Freire | D25: Camino Vitorino Freire | E25: VAGO | F25: MA Norte | G25: DEZ | H25: EDINALDO | J25: 31 | K25: MAT PATIO | L25: Patio Norte | M25: ALEXANDRE | N25: Renata | O25: JUL | P25: CARLA | Q25: Edinaldo | R25: CD 116 | S25: Sim | T25: Mateus | U25: Varejo | V25: =IFERROR(VLOOKUP(Rotas_Geral[[#This Row],[Nome Loja]],#REF!,3,0),0) -> 0 | W25: =IFERROR(VLOOKUP(Rotas_Geral[[#This Row],[Nome Loja]],#REF!,4,0),0) -> 0 | X25: =IFERROR(VLOOKUP(Rotas_Geral[[#This Row],[Nome Loja]],#REF!,3,0),0) -> 0 | Y25: =IFERROR(VLOOKUP(Rotas_Geral[[#This Row],[Nome Loja]],#REF!,4,0),0) -> 0
A26: 17518 | B26: 450 | C26: Camino Ze Doca | D26: Camino Ze Doca | E26: VAGO | F26: MA Norte | G26: DEZ | H26: EDINALDO | J26: 32 | K26: MAT TIMON | L26: Mix Timon | M26: ÉRICA | N26: ÉRICA | O26: JUL | P26: LILIANE | Q26: Edinaldo | R26: CD 116 | S26: Sim | T26: Mateus | U26: Mix | V26: =IFERROR(VLOOKUP(Rotas_Geral[[#This Row],[Nome Loja]],#REF!,3,0),0) -> 0 | W26: =IFERROR(VLOOKUP(Rotas_Geral[[#This Row],[Nome Loja]],#REF!,4,0),0) -> 0 | X26: =IFERROR(VLOOKUP(Rotas_Geral[[#This Row],[Nome Loja]],#REF!,3,0),0) -> 0 | Y26: =IFERROR(VLOOKUP(Rotas_Geral[[#This Row],[Nome Loja]],#REF!,4,0),0) -> 0
A27: 19625 | B27: 47 | C27: MAT BACABAL | D27: Bacabal | E27: VAGO | F27: MA Norte | G27: DEZ | H27: THIEUDE | J27: 34 | K27: MAT JARDIM R | L27: Renascença | M27: RAYARA | N27: MAILANE | O27: JUL | P27: CARLA | Q27: Edinaldo | R27: CD 116 | S27: Sim | T27: Mateus | U27: Varejo | V27: =IFERROR(VLOOKUP(Rotas_Geral[[#This Row],[Nome Loja]],#REF!,3,0),0) -> 0 | W27: =IFERROR(VLOOKUP(Rotas_Geral[[#This Row],[Nome Loja]],#REF!,4,0),0) -> 0 | X27: =IFERROR(VLOOKUP(Rotas_Geral[[#This Row],[Nome Loja]],#REF!,3,0),0) -> 0 | Y27: =IFERROR(VLOOKUP(Rotas_Geral[[#This Row],[Nome Loja]],#REF!,4,0),0) -> 0
A28: 17580 | B28: 48 | C28: MAT MIX PEDR | D28: Mix Pedreiras | E28: VAGO | F28: MA Norte | G28: DEZ | H28: EDINALDO | J28: 35 | K28: MAT CASTANHA | L28: Sup Castanhal | M28: MARÍLIA | N28: MARÍLIA | O28: JUL | P28: THIEUDE | Q28: Edinaldo | R28: CD 106 | S28: Sim | T28: Mateus | U28: Varejo | V28: =IFERROR(VLOOKUP(Rotas_Geral[[#This Row],[Nome Loja]],#REF!,3,0),0) -> 0 | W28: =IFERROR(VLOOKUP(Rotas_Geral[[#This Row],[Nome Loja]],#REF!,4,0),0) -> 0 | X28: =IFERROR(VLOOKUP(Rotas_Geral[[#This Row],[Nome Loja]],#REF!,3,0),0) -> 0 | Y28: =IFERROR(VLOOKUP(Rotas_Geral[[#This Row],[Nome Loja]],#REF!,4,0),0) -> 0
A29: 19624 | B29: 91 | C29: MAT ST I MIX | D29: Mix Santa Inês | E29: BEATRIZ | F29: MA Norte | G29: DEZ | H29: THIEUDE | J29: 36 | K29: MAT ANANINDE | L29: Jaderlândia | M29: RENAN | N29: RENAN | O29: JUL | P29: THIEUDE | Q29: Edinaldo | R29: CD 106 | S29: Sim | T29: Mateus | U29: Varejo | V29: =IFERROR(VLOOKUP(Rotas_Geral[[#This Row],[Nome Loja]],#REF!,3,0),0) -> 0 | W29: =IFERROR(VLOOKUP(Rotas_Geral[[#This Row],[Nome Loja]],#REF!,4,0),0) -> 0 | X29: =IFERROR(VLOOKUP(Rotas_Geral[[#This Row],[Nome Loja]],#REF!,3,0),0) -> 0 | Y29: =IFERROR(VLOOKUP(Rotas_Geral[[#This Row],[Nome Loja]],#REF!,4,0),0) -> 0
A30: 19590 | B30: 3 | C30: MAT. S. INES | D30: Sup Santa Inês | E30: BEATRIZ | F30: MA Norte | G30: DEZ | H30: EDINALDO | J30: 37 | K30: MAT BELEM | L30: Mix Belém | M30: MARIA | N30: MARIA | O30: JUL | P30: THIEUDE | Q30: Edinaldo | R30: CD 106 | S30: Sim | T30: Mateus | U30: Mix | V30: =IFERROR(VLOOKUP(Rotas_Geral[[#This Row],[Nome Loja]],#REF!,3,0),0) -> 0 | W30: =IFERROR(VLOOKUP(Rotas_Geral[[#This Row],[Nome Loja]],#REF!,4,0),0) -> 0 | X30: =IFERROR(VLOOKUP(Rotas_Geral[[#This Row],[Nome Loja]],#REF!,3,0),0) -> 0 | Y30: =IFERROR(VLOOKUP(Rotas_Geral[[#This Row],[Nome Loja]],#REF!,4,0),0) -> 0
A31: 19288 | B31: 42 | C31: Pres Dutra | D31: Presidente Dutra | E31: RAYNARA | F31: MA Norte | G31: DEZ | H31: THIEUDE | J31: 38 | K31: Altamira | L31: Altamira | M31: VAGO | N31: VAGO | O31: JUL | P31: THIEUDE | Q31: Edinaldo | R31: CD 337 | S31: Não | T31: Mateus | U31: Varejo | V31: =IFERROR(VLOOKUP(Rotas_Geral[[#This Row],[Nome Loja]],#REF!,3,0),0) -> 0 | W31: =IFERROR(VLOOKUP(Rotas_Geral[[#This Row],[Nome Loja]],#REF!,4,0),0) -> 0 | X31: =IFERROR(VLOOKUP(Rotas_Geral[[#This Row],[Nome Loja]],#REF!,3,0),0) -> 0 | Y31: =IFERROR(VLOOKUP(Rotas_Geral[[#This Row],[Nome Loja]],#REF!,4,0),0) -> 0
A32: 1281 | B32: 428 | C32: RUANNA SUPER | D32: Ruanna Super | E32: VAGO | F32: MA Norte | G32: DEZ | H32: THIEUDE | J32: 39 | K32: MAT CHAPA | L32: Chapadinha | M32: ÉDINA | N32: ÉDINA | O32: JUL | P32: LILIANE | Q32: Edinaldo | R32: CD 116 | S32: Sim | T32: Mateus | U32: Mix | V32: =IFERROR(VLOOKUP(Rotas_Geral[[#This Row],[Nome Loja]],#REF!,3,0),0) -> 0 | W32: =IFERROR(VLOOKUP(Rotas_Geral[[#This Row],[Nome Loja]],#REF!,4,0),0) -> 0 | X32: =IFERROR(VLOOKUP(Rotas_Geral[[#This Row],[Nome Loja]],#REF!,3,0),0) -> 0 | Y32: =IFERROR(VLOOKUP(Rotas_Geral[[#This Row],[Nome Loja]],#REF!,4,0),0) -> 0
A33: 1282 | B33: 458 | C33: Camino Itinga | D33: Camino Itinga | E33: Vago | F33: Vago | G33: DEZ | H33: THIEUDE | J33: 40 | K33: Barra do Corda | L33: Barra do Corda | M33: VAGO | N33: VAGO | O33: JUL | P33: LILIANE | Q33: Edinaldo | R33: CD 87 | S33: Não | T33: Mateus | U33: Varejo | V33: =IFERROR(VLOOKUP(Rotas_Geral[[#This Row],[Nome Loja]],#REF!,3,0),0) -> 0 | W33: =IFERROR(VLOOKUP(Rotas_Geral[[#This Row],[Nome Loja]],#REF!,4,0),0) -> 0 | X33: =IFERROR(VLOOKUP(Rotas_Geral[[#This Row],[Nome Loja]],#REF!,3,0),0) -> 0 | Y33: =IFERROR(VLOOKUP(Rotas_Geral[[#This Row],[Nome Loja]],#REF!,4,0),0) -> 0
A34: 1284 | B34: 414 | C34: CAMINO ESTREITO | D34: Camino Estreito | E34: VAGO | F34: MA Sul | G34: DEZ | H34: THIEUDE | J34: 41 | K34: CAXIAS | L34: Caxias | M34: F. MAGDA | N34: F. Magda | O34: JUL | P34: LILIANE | Q34: Edinaldo | R34: CD 116 | S34: Sim | T34: Mateus | U34: Mix | V34: =IFERROR(VLOOKUP(Rotas_Geral[[#This Row],[Nome Loja]],#REF!,3,0),0) -> 0 | W34: =IFERROR(VLOOKUP(Rotas_Geral[[#This Row],[Nome Loja]],#REF!,4,0),0) -> 0 | X34: =IFERROR(VLOOKUP(Rotas_Geral[[#This Row],[Nome Loja]],#REF!,3,0),0) -> 0 | Y34: =IFERROR(VLOOKUP(Rotas_Geral[[#This Row],[Nome Loja]],#REF!,4,0),0) -> 0
A35: 3897 | B35: 44 | C35: Babaçulândia | D35: Babaçulândia | E35: DEYMERSON | F35: MA Sul | G35: DEZ | H35: THIEUDE | J35: 42 | K35: Pres Dutra | L35: Presidente Dutra | M35: VAGO | N35: VAGO | O35: JUL | P35: LILIANE | Q35: Edinaldo | R35: CD 87 | S35: Não | T35: Mateus | U35: Varejo | V35: =IFERROR(VLOOKUP(Rotas_Geral[[#This Row],[Nome Loja]],#REF!,3,0),0) -> 0 | W35: =IFERROR(VLOOKUP(Rotas_Geral[[#This Row],[Nome Loja]],#REF!,4,0),0) -> 0 | X35: =IFERROR(VLOOKUP(Rotas_Geral[[#This Row],[Nome Loja]],#REF!,3,0),0) -> 0 | Y35: =IFERROR(VLOOKUP(Rotas_Geral[[#This Row],[Nome Loja]],#REF!,4,0),0) -> 0
A36: 17050 | B36: 432 | C36: CAMINO CAROLINA | D36: Camino Carolina | E36: VAGO | F36: MA Sul | G36: DEZ | H36: THIEUDE | J36: 44 | K36: Babaçulândia | L36: Babaçulândia | M36: NARGILA | N36: ANGELA | O36: JUL | P36: THIEUDE | Q36: Edinaldo | R36: CD 87 | S36: Sim | T36: Mateus | U36: Mix | V36: =IFERROR(VLOOKUP(Rotas_Geral[[#This Row],[Nome Loja]],#REF!,3,0),0) -> 0 | W36: =IFERROR(VLOOKUP(Rotas_Geral[[#This Row],[Nome Loja]],#REF!,4,0),0) -> 0 | X36: =IFERROR(VLOOKUP(Rotas_Geral[[#This Row],[Nome Loja]],#REF!,3,0),0) -> 0 | Y36: =IFERROR(VLOOKUP(Rotas_Geral[[#This Row],[Nome Loja]],#REF!,4,0),0) -> 0
A37: 17510 | B37: 438 | C37: CAMINO GRAJAU | D37: Camino Grajaú | E37: VAGO | F37: MA Sul | G37: DEZ | H37: THIEUDE | J37: 45 | K37: MATEUS MARAN | L37: Marambaia | M37: RENAN | N37: RENAN | O37: JUL | P37: THIEUDE | Q37: Edinaldo | R37: CD 106 | S37: Sim | T37: Mateus | U37: Varejo | V37: =IFERROR(VLOOKUP(Rotas_Geral[[#This Row],[Nome Loja]],#REF!,3,0),0) -> 0 | W37: =IFERROR(VLOOKUP(Rotas_Geral[[#This Row],[Nome Loja]],#REF!,4,0),0) -> 0 | X37: =IFERROR(VLOOKUP(Rotas_Geral[[#This Row],[Nome Loja]],#REF!,3,0),0) -> 0 | Y37: =IFERROR(VLOOKUP(Rotas_Geral[[#This Row],[Nome Loja]],#REF!,4,0),0) -> 0
... A40: 2645 | B40: 2 | C40: MAT. I. CE | D40: Ceará | E40: ANGELA | F40: MA Sul | G40: DEZ | H40: THIEUDE | J40: 48 | K40: MAT MIX PEDR | L40: Mix Pedreiras | M40: VAGO | N40: VAGO | O40: JUL | P40: LILIANE | Q40: Edinaldo | R40: CD 116 | S40: Não | T40: Mateus | U40: Mix | V40: =IFERROR(VLOOKUP(Rotas_Geral[[#This Row],[Nome Loja]],#REF!,3,0),0) -> 0 | W40: =IFERROR(VLOOKUP(Rotas_Geral[[#This Row],[Nome Loja]],#REF!,4,0),0) -> 0 | X40: =IFERROR(VLOOKUP(Rotas_Geral[[#This Row],[Nome Loja]],#REF!,3,0),0) -> 0 | Y40: =IFERROR(VLOOKUP(Rotas_Geral[[#This Row],[Nome Loja]],#REF!,4,0),0) -> 0
B41: 4 | C41: MAT. I. GOIA | D41: Goiás | E41: ANGELA | F41: MA Sul | G41: DEZ | H41: THIEUDE | J41: 49 | K41: MAT CAST MIX | L41: Mix Castanhal | M41: MARÍLIA | N41: MARÍLIA | O41: JUL | P41: THIEUDE | Q41: Edinaldo | R41: CD 106 | S41: Sim | T41: Mateus | U41: Mix | V41: =IFERROR(VLOOKUP(Rotas_Geral[[#This Row],[Nome Loja]],#REF!,3,0),0) -> 0 | W41: =IFERROR(VLOOKUP(Rotas_Geral[[#This Row],[Nome Loja]],#REF!,4,0),0) -> 0 | X41: =IFERROR(VLOOKUP(Rotas_Geral[[#This Row],[Nome Loja]],#REF!,3,0),0) -> 0 | Y41: =IFERROR(VLOOKUP(Rotas_Geral[[#This Row],[Nome Loja]],#REF!,4,0),0) -> 0
A42: #N/A | B42: 92 | C42: MATEUS BAC 2 | D42: Bacuri | E42: RARIEL | F42: MA Sul | G42: DEZ | H42: THIEUDE | J42: 50 | K42: Abaetetuba | L42: Abaetetuba | M42: VAGO | N42: VAGO | O42: JUL | P42: THIEUDE | Q42: Edinaldo | R42: CD 106 | S42: Não | T42: Mateus | U42: Varejo | V42: =IFERROR(VLOOKUP(Rotas_Geral[[#This Row],[Nome Loja]],#REF!,3,0),0) -> 0 | W42: =IFERROR(VLOOKUP(Rotas_Geral[[#This Row],[Nome Loja]],#REF!,4,0),0) -> 0 | X42: =IFERROR(VLOOKUP(Rotas_Geral[[#This Row],[Nome Loja]],#REF!,3,0),0) -> 0 | Y42: =IFERROR(VLOOKUP(Rotas_Geral[[#This Row],[Nome Loja]],#REF!,4,0),0) -> 0
A43: #N/A | B43: 95 | C43: MATEUS RODOV | D43: Tamandaré | E43: RARIEL | F43: MA Sul | G43: DEZ | H43: THIEUDE | J43: 51 | K43: MARITUBA | L43: Marituba | M43: RENAN | N43: DIEGO | O43: JUL | P43: THIEUDE | Q43: Edinaldo | R43: CD 106 | S43: Sim | T43: Mateus | U43: Varejo | V43: =IFERROR(VLOOKUP(Rotas_Geral[[#This Row],[Nome Loja]],#REF!,3,0),0) -> 0 | W43: =IFERROR(VLOOKUP(Rotas_Geral[[#This Row],[Nome Loja]],#REF!,4,0),0) -> 0 | X43: =IFERROR(VLOOKUP(Rotas_Geral[[#This Row],[Nome Loja]],#REF!,3,0),0) -> 0 | Y43: =IFERROR(VLOOKUP(Rotas_Geral[[#This Row],[Nome Loja]],#REF!,4,0),0) -> 0
A44: #N/A | B44: 52 | C44: Mix Açailandia | D44: Mix Açailândia | E44: ANDRESSA | F44: MA Sul | G44: DEZ | H44: THIEUDE | J44: 52 | K44: Mix Açailandia | L44: Mix Açailândia | M44: ISRAEL | N44: ISRAEL | O44: JUL | P44: THIEUDE | Q44: Edinaldo | R44: CD 87 | S44: Sim | T44: Mateus | U44: Mix | V44: =IFERROR(VLOOKUP(Rotas_Geral[[#This Row],[Nome Loja]],#REF!,3,0),0) -> 0 | W44: =IFERROR(VLOOKUP(Rotas_Geral[[#This Row],[Nome Loja]],#REF!,4,0),0) -> 0 | X44: =IFERROR(VLOOKUP(Rotas_Geral[[#This Row],[Nome Loja]],#REF!,3,0),0) -> 0 | Y44: =IFERROR(VLOOKUP(Rotas_Geral[[#This Row],[Nome Loja]],#REF!,4,0),0) -> 0
A45: #N/A | B45: 94 | C45: Mix Balsas | D45: Mix Balsas | E45: ROSICLEIA | F45: MA Sul | G45: DEZ | H45: THIEUDE | J45: 87 | K45: CD 87 | L45: CD 87 | M45: NARGILA | N45: NARGILA | O45: JUL | P45: Lucas | Q45: Vago | R45: CD 87 | S45: Sim | T45: Mateus | U45: CD | V45: =IFERROR(VLOOKUP(Rotas_Geral[[#This Row],[Nome Loja]],#REF!,3,0),0) -> 0 | W45: =IFERROR(VLOOKUP(Rotas_Geral[[#This Row],[Nome Loja]],#REF!,4,0),0) -> 0 | X45: =IFERROR(VLOOKUP(Rotas_Geral[[#This Row],[Nome Loja]],#REF!,3,0),0) -> 0 | Y45: =IFERROR(VLOOKUP(Rotas_Geral[[#This Row],[Nome Loja]],#REF!,4,0),0) -> 0
A46: #N/A | B46: 213 | C46: Super Estreito | D46: Super Estreito | E46: VAGO | F46: MA Sul | G46: DEZ | H46: THIEUDE | J46: 91 | K46: MAT ST I MIX | L46: Mix Santa Inês | M46: BEATRIZ | N46: BEATRIZ | O46: JUL | P46: LILIANE | Q46: Edinaldo | R46: CD 116 | S46: Sim | T46: Mateus | U46: Mix | V46: =IFERROR(VLOOKUP(Rotas_Geral[[#This Row],[Nome Loja]],#REF!,3,0),0) -> 0 | W46: =IFERROR(VLOOKUP(Rotas_Geral[[#This Row],[Nome Loja]],#REF!,4,0),0) -> 0 | X46: =IFERROR(VLOOKUP(Rotas_Geral[[#This Row],[Nome Loja]],#REF!,3,0),0) -> 0 | Y46: =IFERROR(VLOOKUP(Rotas_Geral[[#This Row],[Nome Loja]],#REF!,4,0),0) -> 0
A47: #N/A | B47: 50 | C47: Abaetetuba | D47: Abaetetuba | E47: VAGO | F47: Pará Norte | G47: DEZ | H47: THIEUDE | J47: 92 | K47: MATEUS BAC 2 | L47: Bacuri | M47: RARIEL | N47: ANGELA | O47: JUL | P47: THIEUDE | Q47: Edinaldo | R47: CD 87 | S47: Sim | T47: Mateus | U47: Mix | V47: =IFERROR(VLOOKUP(Rotas_Geral[[#This Row],[Nome Loja]],#REF!,3,0),0) -> 0 | W47: =IFERROR(VLOOKUP(Rotas_Geral[[#This Row],[Nome Loja]],#REF!,4,0),0) -> 0 | X47: =IFERROR(VLOOKUP(Rotas_Geral[[#This Row],[Nome Loja]],#REF!,3,0),0) -> 0 | Y47: =IFERROR(VLOOKUP(Rotas_Geral[[#This Row],[Nome Loja]],#REF!,4,0),0) -> 0
A48: 12564 | B48: 204 | C48: BARCARENA | D48: Barcarena | E48: Intermitente Barcarena | F48: Pará Norte | G48: DEZ | H48: EDINALDO | J48: 93 | K48: MATEUS MAIOB | L48: Maiobão | M48: VAGO | N48: Renata | O48: JUL | P48: CARLA | Q48: Edinaldo | R48: CD 116 | S48: Não | T48: Mateus | U48: Mix | V48: =IFERROR(VLOOKUP(Rotas_Geral[[#This Row],[Nome Loja]],#REF!,3,0),0) -> 0 | W48: =IFERROR(VLOOKUP(Rotas_Geral[[#This Row],[Nome Loja]],#REF!,4,0),0) -> 0 | X48: =IFERROR(VLOOKUP(Rotas_Geral[[#This Row],[Nome Loja]],#REF!,3,0),0) -> 0 | Y48: =IFERROR(VLOOKUP(Rotas_Geral[[#This Row],[Nome Loja]],#REF!,4,0),0) -> 0
A49: 12569 | B49: 267 | C49: Bragança | D49: Bragança | E49: VAGO | F49: Pará Norte | G49: DEZ | H49: EDINALDO | J49: 94 | K49: Mix Balsas | L49: Mix Balsas | M49: ROSICLEIA | N49: ROSICLEIA | O49: JUL | P49: THIEUDE | Q49: Edinaldo | R49: CD 87 | S49: Sim | T49: Mateus | U49: Mix | V49: =IFERROR(VLOOKUP(Rotas_Geral[[#This Row],[Nome Loja]],#REF!,3,0),0) -> 0 | W49: =IFERROR(VLOOKUP(Rotas_Geral[[#This Row],[Nome Loja]],#REF!,4,0),0) -> 0 | X49: =IFERROR(VLOOKUP(Rotas_Geral[[#This Row],[Nome Loja]],#REF!,3,0),0) -> 0 | Y49: =IFERROR(VLOOKUP(Rotas_Geral[[#This Row],[Nome Loja]],#REF!,4,0),0) -> 0
A50: 12575 | B50: 449 | C50: Camino Goianesia | D50: Camino Goianesia | E50: VAGO | F50: Pará Norte | G50: DEZ | H50: EDINALDO | J50: 95 | K50: MATEUS RODOV | L50: Tamandaré | M50: RARIEL | N50: ANGELA | O50: JUL | P50: THIEUDE | Q50: Edinaldo | R50: CD 87 | S50: Sim | T50: Mateus | U50: Mix | V50: =IFERROR(VLOOKUP(Rotas_Geral[[#This Row],[Nome Loja]],#REF!,3,0),0) -> 0 | W50: =IFERROR(VLOOKUP(Rotas_Geral[[#This Row],[Nome Loja]],#REF!,4,0),0) -> 0 | X50: =IFERROR(VLOOKUP(Rotas_Geral[[#This Row],[Nome Loja]],#REF!,3,0),0) -> 0 | Y50: =IFERROR(VLOOKUP(Rotas_Geral[[#This Row],[Nome Loja]],#REF!,4,0),0) -> 0
A51: 13777 | B51: 263 | C51: Mario Covas | D51: Mario Covas | E51: Cleane | F51: Pará Norte | G51: DEZ | H51: EDINALDO | J51: 96 | K51: MAT. JOAO PA | L51: João Paulo | M51: VAGO | N51: WILIANE | O51: JUL | P51: CARLA | Q51: Edinaldo | R51: CD 116 | S51: Não | T51: Mateus | U51: Mix | V51: =IFERROR(VLOOKUP(Rotas_Geral[[#This Row],[Nome Loja]],#REF!,3,0),0) -> 0 | W51: =IFERROR(VLOOKUP(Rotas_Geral[[#This Row],[Nome Loja]],#REF!,4,0),0) -> 0 | X51: =IFERROR(VLOOKUP(Rotas_Geral[[#This Row],[Nome Loja]],#REF!,3,0),0) -> 0 | Y51: =IFERROR(VLOOKUP(Rotas_Geral[[#This Row],[Nome Loja]],#REF!,4,0),0) -> 0
A52: 14569 | B52: 51 | C52: MARITUBA | D52: Marituba | E52: NAYARA | F52: Pará Norte | G52: DEZ | H52: EDINALDO | J52: 97 | K52: Mat Livram | L52: Ceasa Teresina | M52: ÉRICA | N52: ÉRICA | O52: JUL | P52: LILIANE | Q52: Edinaldo | R52: CD 116 | S52: Sim | T52: Mateus | U52: Mix | V52: =IFERROR(VLOOKUP(Rotas_Geral[[#This Row],[Nome Loja]],#REF!,3,0),0) -> 0 | W52: =IFERROR(VLOOKUP(Rotas_Geral[[#This Row],[Nome Loja]],#REF!,4,0),0) -> 0 | X52: =IFERROR(VLOOKUP(Rotas_Geral[[#This Row],[Nome Loja]],#REF!,3,0),0) -> 0 | Y52: =IFERROR(VLOOKUP(Rotas_Geral[[#This Row],[Nome Loja]],#REF!,4,0),0) -> 0
...

Sheet Regras Premiação (3)
C2: Promotor | D2: A+ (c/ Trebeschi) | E2: BASE: | F2: 1500 | G2: A+ | K2: Coordenador | L2: A+ | Venda > 1.750.000 | M2: BASE: | N2: 2000 | T2: PROMOTORIA | U2: RESUMO DE NÍVEIS | Z2: COORDENAÇÃO | AA2: RESUMO DE NÍVEIS | AH2: Supervisor | AI2: - | AJ2: Ago | AP2: Gerente | AQ2: - | AR2: Ago
A3: Regras: | C3: Objetivo | I3: Regras: | K3: Objetivo | T3: NÍVEL | U3: 0.9 | V3: 1 | W3: 1.15 | Z3: NÍVEL | AA3: 0.9 | AB3: 1 | AC3: 1.15 | AF3: Regras: | AH3: Objetivo | AN3: Regras: | AP3: Objetivo
A4: 1º | C4: Chegar na Meta Sell-Out | E4: 0.9 | F4: 1 | G4: 1.15 | I4: 1º | K4: Chegar na Meta Sell-Out | M4: 0.9 | N4: 1 | O4: 1.15 | T4: A+ | U4: =E19 -> 100 | V4: =F19 -> 200 | W4: =G19 -> 270 | Z4: A+ | AA4: 135 | AB4: 270 | AC4: 350 | AF4: 1º | AH4: Chegar na Meta Sell-Out | AJ4: 0.9 | AK4: 1 | AL4: 1.15 | AN4: 1º | AP4: Chegar na Meta Sell-Out | AR4: 0.9 | AS4: 1 | AT4: 1.15
C5: A: | D5: Atingimento Total Master | E5: =E18/$F$29 -> 0.041666667 | F5: =F18/$F$29 -> 0.083333333 | G5: =G18/$F$29 -> 0.125 | K5: A: | L5: Atingimento Total Master | M5: 0.05 | N5: 0.1 | O5: 0.15 | T5: A | U5: =E44 -> 85 | V5: =F44 -> 170 | W5: =G44 -> 200 | Z5: A | AA5: 112.5 | AB5: 225 | AC5: 270 | AH5: A: | AI5: Atingimento Total Master | AJ5: 130 | AK5: 250 | AL5: 360 | AP5: A: | AQ5: Atingimento Total Master | AR5: 170 | AS5: 300 | AT5: 440
C6: B: | D6: Atingimento Individual Avine | E6: =E19/$F$29 -> 0.055555556 | F6: =F19/$F$29 -> 0.11111111 | G6: =G19/$F$29 -> 0.15 | K6: B: | L6: Atingimento Individual Avine | M6: 0.075 | N6: 0.15 | O6: 0.2 | T6: B | U6: =E73 -> 70 | V6: =F73 -> 140 | W6: =G73 -> 175 | Z6: B | AA6: 85 | AB6: 170 | AC6: 220 | AH6: B: | AI6: Atingimento Individual Avine | AJ6: 150 | AK6: 350 | AL6: 440 | AP6: B: | AQ6: Atingimento Individual Avine | AR6: 170 | AS6: 400 | AT6: 500
C7: C: | D7: Atingimento Individual Capp | E7: =E20/$F$29 -> 0.055555556 | F7: =F20/$F$29 -> 0.11111111 | G7: =G20/$F$29 -> 0.15 | K7: C: | L7: Atingimento Individual Capp | M7: 0.15 | N7: 0.3 | O7: 0.4 | T7: C | U7: =E102 -> 50 | V7: =F102 -> 100 | W7: =G102 -> 125 | AH7: C: | AI7: Atingimento Individual Capp | AJ7: 150 | AK7: 350 | AL7: 440 | AP7: =AH7 -> C: | AQ7: Atingimento Individual Capp | AR7: 170 | AS7: 400 | AT7: 500
C8: D: | D8: Atingimento Individual Famosa | E8: =E21/$F$29 -> 0.055555556 | F8: =F21/$F$29 -> 0.11111111 | G8: =G21/$F$29 -> 0.15
C9: E: | D9: Atingimento Individual S&V | E9: =E22/$F$29 -> 0.11111111 | F9: =F22/$F$29 -> 0.22222222 | G9: =G22/$F$29 -> 0.3 | K9: D: | L9: Atingimento Individual Famosa | M9: 0.075 | N9: 0.15 | O9: 0.2 | AF9: 2 | AH9: Devolução < 1,5% | AI9: Atingimento Individual Avine | AJ9: 400 | AK9: 400 | AL9: 400 | AN9: 2 | AP9: Devolução < 1,5% | AQ9: Atingimento Individual Avine | AR9: 450 | AS9: 450 | AT9: 450
C10: F: | D10: Atingimento Individual Trebeschi | E10: =E23/$F$29 -> 0.055555556 | F10: =F23/$F$29 -> 0.11111111 | G10: =G23/$F$29 -> 0.15 | T10: Auxiliares
AF11: 3 | AH11: Avaliação Gestor | AI11: Atingimento Total Master | AJ11: 400 | AK11: 400 | AL11: 400 | AN11: 3 | AP11: Avaliação Gestor | AQ11: Atingimento Total Master | AR11: 450 | AS11: 450 | AT11: 450
A12: 2 | C12: Devolução <= 1% | D12: Atingimento Individual Avine | E12: =E25/$F$29 -> 0.125 | F12: =F25/$F$29 -> 0.125 | G12: =G25/$F$29 -> 0.125 | I12: 2 | K12: Devolução < 1% | L12: Atingimento Individual Avine | M12: 0.15 | N12: 0.15 | O12: 0.15 | T12: Premiação Master
T13: Resultado Master | U13: 0.9 | V13: 1 | W13: 1.15 | AI13: Total | AJ13: =SUM(AJ5:AJ11) -> 1230 | AK13: =SUM(AK5:AK11) -> 1750 | AL13: =SUM(AL5:AL11) -> 2040 | AQ13: Total | AR13: =SUM(AR5:AR11) -> 1410 | AS13: =SUM(AS5:AS11) -> 2000 | AT13: =SUM(AT5:AT11) -> 2340
A14: 3 | C14: Avaliação Gestor | D14: Atingimento Total Master | E14: =E27/$F$29 -> 0.125 | F14: =F27/$F$29 -> 0.125 | G14: 0.15 | I14: 3 | K14: Avaliação Gestor | L14: Atingimento Total Master | M14: 0.15 | N14: 0.15 | O14: 0.15 | T14: Auxiliar | U14: 75 | V14: 150 | W14: 225
E15: =SUM(E5:E14) -> 0.625 | F15: =SUM(F5:F14) -> 1 | G15: =SUM(G5:G14) -> 1.3 | M15: 0.65 | N15: 1 | O15: 1.2 | T15: Coordenador | U15: 100 | V15: 200 | W15: 300 | AI15: Total Edinaldo | AJ15: 1350 | AQ15: Total Raianne | AR15: 1420
A16: Regras: | C16: Objetivo | I16: Regras: | K16: Objetivo
A17: 1º | C17: Chegar na Meta Sell-Out | E17: 0.9 | F17: 1 | G17: 1.15 | I17: 1º | K17: Chegar na Meta Sell-Out | M17: 0.9 | N17: 1 | O17: 1.15
C18: A: | D18: Atingimento Total Master | E18: 75 | F18: 150 | G18: 225 | K18: A: | L18: Atingimento Total Master | M18: 100 | N18: 200 | O18: 300
C19: B: | D19: Atingimento Individual Avine | E19: 100 | F19: 200 | G19: 270 | K19: B: | L19: Atingimento Individual Avine | M19: =N19/2 -> 135 | N19: 270 | O19: 350 | T19: PROMOTORIA | U19: Média
C20: C: | D20: Atingimento Individual Capp | E20: 100 | F20: 200 | G20: 270 | K20: C: | L20: Atingimento Individual Capp | M20: =N20/2 -> 135 | N20: 270 | O20: 350 | T20: NÍVEL | U20: 0.6
C21: D: | D21: Atingimento Individual Famosa | E21: 100 | F21: 200 | G21: 270 | K21: D: | L21: Atingimento Individual Famosa | M21: =N21/2 -> 135 | N21: 270 | O21: 350 | T21: A+ | U21: =U20*F29 -> 1080
C22: E: | D22: Atingimento Individual S&V | E22: 200 | F22: 400 | G22: 540 | K22: E: | L22: Atingimento Individual S&V | M22: =N22/2 -> 135 | N22: 270 | O22: 350 | T22: A | U22: =U20*F54 -> 972
C23: F: | D23: Atingimento Individual Trebeschi | E23: 100 | F23: 200 | G23: 270
T24: B | U24: =U20*F83 -> 864
A25: 2 | C25: Devolução <= 1% | D25: Atingimento Individual Avine | E25: 225 | F25: 225 | G25: 225 | I25: 2 | K25: Devolução < 1% | L25: Atingimento Individual Avine | M25: 300 | N25: 300 | O25: 300 | T25: C | U25: =U20*F112 -> 720
A27: 3 | C27: Avaliação Gestor | D27: Avaliação | E27: 225 | F27: 225 | G27: 225 | I27: 3 | K27: Avaliação Gestor | L27: Atingimento Total Master | M27: 300 | N27: 300 | O27: 300
D29: Total | E29: =SUM(E18:E27) -> 1125 | F29: =SUM(F18:F27) -> 1800 | G29: =SUM(G18:G27) -> 2295 | L29: Total ( Incluindo a marca do Mês) | M29: =SUM(M18:M27)+M22 -> 1375 | N29: =SUM(N18:N27)+N22 -> 2150 | O29: =SUM(O18:O27)+O22 -> 2650 | T29: PROMOTORIA | U29: Premiação por Marca
T30: NÍVEL ( Sell out ) | U30: 0.9 | V30: 1 | W30: 1.15
C31: Promotor | D31: A | Venda > 260.000 | E31: BASE: | F31: 1500 | G31: A | K31: Coordenador | L31: A | Venda > 1.000.000 | M31: BASE: | N31: 2000 | T31: - | U31: 100 | V31: 200 | W31: 270
C32: B: | D32: Atingimento Individual Avine | E32: 0.0625 | F32: 0.125 | G32: 0.15 | K32: B: | L32: Atingimento Individual Avine | M32: 0.0625 | N32: 0.125 | O32: 0.15
C33: C: | D33: Atingimento Individual Capp | E33: 0.125 | F33: 0.25 | G33: 0.3 | K33: C: | L33: Atingimento Individual Capp | M33: 0.125 | N33: 0.25 | O33: 0.3
C34: D: | D34: Atingimento Individual Famosa | E34: 0.0625 | F34: 0.125 | G34: 0.15 | K34: D: | L34: Atingimento Individual Famosa | M34: 0.0625 | N34: 0.125 | O34: 0.15 | T34: Aitividades Extras
T35: Função | V35: 0.9 | W35: 1
T36: Atividade 1 | V36: 56.25 | W36: =W37 -> 112.5
A37: 2 | C37: Devolução <= 1% | D37: Atingimento Individual Avine | E37: 0.15 | F37: 0.15 | G37: 0.15 | I37: 2 | K37: Devolução < 1% | L37: Atingimento Individual Avine | M37: 0.15 | N37: 0.15 | O37: 0.15 | T37: Atividade 2 | V37: =V36 -> 56.25 | W37: =V37*2 -> 112.5
A39: 3 | C39: Avaliação Gestor | D39: Atingimento Total Master | E39: 0.15 | F39: 0.15 | G39: 0.15 | I39: 3 | K39: Avaliação Gestor | L39: Atingimento Total Master | M39: 0.15 | N39: 0.15 | O39: 0.15
E40: 0.6 | F40: 0.9 | G40: 1.05 | M40: 0.6 | N40: 0.9 | O40: 1.05 | T40: Devolução Avine
A41: Regras: | C41: Objetivo | I41: Regras: | K41: Objetivo | T41: Atingimento <= 1.5% | V41: 225
A42: 1º | C42: Chegar na Meta Sell-Out | E42: 0.9 | F42: 1 | G42: 1.15 | I42: 1º | K42: Chegar na Meta Sell-Out | M42: 0.9 | N42: 1 | O42: 1.15
C43: A: | D43: Atingimento Total Master | E43: 75 | F43: 150 | G43: 225 | K43: A: | L43: Atingimento Total Master | M43: 100 | N43: 200 | O43: 300
C44: B: | D44: Atingimento Individual Avine | E44: 85 | F44: 170 | G44: 200 | K44: B: | L44: Atingimento Individual Avine | M44: =N44/2 -> 112.5 | N44: 225 | O44: 270
...

Sheet Quadro Geral Teste
A1: Marca do Mês MA | F1: Mês | H1: % Master
A2: Marca do Mês PA | F2: ABR | H2: 1.1037
A4: CLEANE BRANDAO
E5: Avine | G5: Cappellaro | I5: Famosa | K5: S&V | M5: Trebeschi | AB5: Avine | AD5: Cappellaro | AF5: Famosa | AH5: S&V | AJ5: Trebeschi
E6: =SUBTOTAL(109,Promotores9[R$ Avi]) -> 0 | G6: =SUBTOTAL(109,Promotores9[R$ Capp]) -> 0 | I6: =SUBTOTAL(109,Promotores9[R$ Fam]) -> 0 | K6: =SUBTOTAL(109,Promotores9[R$ S&V]) -> 0 | M6: =SUBTOTAL(109,Promotores9[R$ Treb]) -> 0 | N6: =SUBTOTAL(109,Promotores9[Master]) -> 150 | O6: =SUBTOTAL(109,Promotores9[APP]) -> 0 | Q6: =SUBTOTAL(109,Promotores9[R$ Dev]) -> 0 | R6: =SUBTOTAL(109,Promotores9[Total]) -> 600 | AB6: =SUBTOTAL(109,Coordenadores10[R$ Avi]) -> 0 | AD6: =SUBTOTAL(109,Coordenadores10[R$ Capp]) -> 0 | AF6: =SUBTOTAL(109,Coordenadores10[R$ Fam]) -> 0 | AH6: =SUBTOTAL(109,Coordenadores10[R$ S&V]) -> 0 | AK6: =SUBTOTAL(109,Coordenadores10[Master]) -> 200 | AL6: =SUBTOTAL(109,Coordenadores10[Gestor]) -> 1200 | AN6: =SUBTOTAL(109,Promotores9[R$ Dev]) -> 0 | AO6: =SUBTOTAL(109,Coordenadores10[Total]) -> #REF!
A7: Promotor | B7: Sell Out | C7: Nível | D7: % Avi | E7: R$ Avi | F7: % Capp | G7: R$ Capp | H7: % Fam | I7: R$ Fam | J7: % S&V | K7: R$ S&V | L7: % Treb | M7: R$ Treb | N7: Master | O7: APP | P7: % Dev | Q7: R$ Dev | R7: Total | S7: Regional | T7: Estoque | U7: Preço | X7: Coordenador | Y7: Sell Out | Z7: Nível | AA7: % Avi | AB7: R$ Avi | AC7: % Capp | AD7: R$ Capp | AE7: % Fam | AF7: R$ Fam | AG7: % S&V | AH7: R$ S&V | AI7: % Treb | AJ7: R$ Treb | AK7: Master | AL7: Gestor | AM7: % Dev | AN7: R$ Dev | AO7: Total
